const retryOnError = async (asyncFn, onError) => {
  while (true) {
    try {
      return await asyncFn();
    } catch (e) {
      onError(e);
    }
  }
};

export default retryOnError;
